<?xml version="1.0"?>
<robot name="myfirst">
  <material name="blue">
    <color rgba="0 0 0.8 1"/>
  </material>
  <material name="white">
    <color rgba="1 1 1 1"/>
  </material>
  <material name="other">
    <color rgba="1 0 0.8 1"/>
  </material>

  <link name="Base">
    <visual>
      <geometry>
        <box size="0.3 0.3 1"/>
      </geometry>
      <material name="white"/>
    </visual>
    <collision>
      <geometry>
        <box size="0.3 0.3 1"/>
      </geometry>
    </collision>
    <inertial>
      <mass value="100"/>
      <origin rpy="0 0 0" xyz="0 0 0"/>
      <inertia ixx="0" ixy="0.0" ixz="0.0" iyy="0" iyz="0.0" izz="0"/>
    </inertial>
  </link>

  <link name="base2">
    <visual>
      <geometry>
        <box size="0.3 0.3 2"/>                 <!--aparatus legnth increment-->
      </geometry>
      <material name="white"/>
    </visual>
    <collision>
      <geometry>
        <box size="0.3 0.3 2"/>                 <!--aparatus legnth increment-->
      </geometry>
    </collision>
    <inertial>
      <mass value="100"/>
      <origin rpy="0 0 0" xyz="0 0 0"/>
      <inertia ixx="0" ixy="0.0" ixz="0.0" iyy="0" iyz="0.0" izz="0"/>
    </inertial>
  </link>

  <joint name="base1_base2" type="fixed">
    <parent link="Base"/>
    <child link="base2"/>
    <origin rpy="0 1.57075 0" xyz="1.15 0 -.35"/>    <!--ANGLE DISPLACEMENT!!!-->     <!--aparatus legnth increment-->
  </joint>

  <link name="base3">
    <visual>
      <geometry>
        <box size="0.3 0.3 .89"/>                          <!--Short base-->
      </geometry>
      <material name="white"/>
    </visual>
    <collision>
      <geometry>
        <box size="0.3 0.3 .9"/>                         <!--short base-->
      </geometry>
    </collision>
    <inertial>
      <mass value="100"/>
      <origin rpy="0 0 0" xyz="0 0 0"/>
      <inertia ixx="0" ixy="0.0" ixz="0.0" iyy="0" iyz="0.0" izz="0"/>
    </inertial>
  </link>

  <joint name="base2_base3" type="fixed">
    <parent link="base2"/>
    <child link="base3"/>
    <origin rpy="0 1.57075 0" xyz="-.295 0 1.15"/>    <!--ANGLE DISPLACEMENT!!!-->      <!--aparatus legnth increment-->
  </joint>

  <link name="base4">
    <visual>
      <geometry>
        <box size="0.1 0.1 .3"/>
        <!--Short base-->
      </geometry>
      <material name="white"/>
    </visual>
    <collision>
      <geometry>
        <box size="0.1 0.1 .3"/>
        <!--short base-->
      </geometry>
    </collision>
    <inertial>
      <mass value="100"/>
      <origin rpy="0 0 0" xyz="0 0 0"/>
      <inertia ixx="0" ixy="0.0" ixz="0.0" iyy="0" iyz="0.0" izz="0"/>
    </inertial>
  </link>

  <joint name="base3_base4" type="fixed">
    <parent link="base3"/>
    <child link="base4"/>
    <origin rpy="0 0 0" xyz=".21 .09 -.45"/>
  </joint>

  <link name="base5">
    <visual>
      <geometry>
        <box size="0.1 0.1 .3"/>
        <!--Short base-->
      </geometry>
      <material name="white"/>
    </visual>
    <collision>
      <geometry>
        <box size="0.1 0.1 .3"/>
        <!--short base-->
      </geometry>
    </collision>
    <inertial>
      <mass value="100"/>
      <origin rpy="0 0 0" xyz="0 0 0"/>
      <inertia ixx="0" ixy="0.0" ixz="0.0" iyy="0" iyz="0.0" izz="0"/>
    </inertial>
  </link>

  <joint name="base3_base5" type="fixed">
    <parent link="base3"/>
    <child link="base5"/>
    <origin rpy="0 0 0" xyz="-0.01 .09 -.45"/>
  </joint>

  <link name="base6">
    <visual>
      <geometry>
        <box size="0.1 0.1 .3"/>
        <!--Short base-->
      </geometry>
      <material name="white"/>
    </visual>
    <collision>
      <geometry>
        <box size="0.1 0.1 .3"/>
        <!--short base-->
      </geometry>
    </collision>
    <inertial>
      <mass value="100"/>
      <origin rpy="0 0 0" xyz="0 0 0"/>
      <inertia ixx="0" ixy="0.0" ixz="0.0" iyy="0" iyz="0.0" izz="0"/>
    </inertial>
  </link>

  <joint name="base3_base6" type="fixed">
    <parent link="base3"/>
    <child link="base6"/>
    <origin rpy="0 1.57075 0" xyz=".1 .09 -.61"/>
  </joint>
  
  <!--Moving mechanism-->
  
  <link name="axis1">
    <visual>
      <geometry>
        <box size="0.1 0.1 0.1"/>
      </geometry>
      <material name="blue"/>
    </visual>
    <collision>
      <geometry>
        <box size="0.1 0.1 0.1"/>
      </geometry>
    </collision>
    <inertial>
      <mass value="100"/>
      <origin rpy="0 0 0" xyz="0 0 0"/>
      <inertia ixx="0" ixy="0.0" ixz="0.0" iyy="0" iyz="0.0" izz="0"/>
    </inertial>
  </link>

  <!--link name="pulley1">
    <visual>
      <geometry>
        <cylinder length=".05" radius="1"/>
      </geometry>
      <material name="blue"/>
    </visual>
    <collision>
      <geometry>
        <cylinder length=".05" radius="1"/>
      </geometry>
    </collision>
    <inertial>
      <mass value="1"/>
      <inertia ixx="0.0" ixy="0.0" ixz="0.0" iyy="0.0" iyz="0.0" izz="0.0"/>
    </inertial>
  </link-->

  <joint name="Base_axis1" type="revolute"> <!--Make revolute joint later-->
    <axis xyz="0 1 0"/>
    <parent link="Base"/>
    <child link="axis1"/>
    <limit effort="0" lower="1" upper="0" velocity="205"/>
    <origin rpy="0 0 0" xyz=".1 .2 .45"/>
  </joint>
  
  <link name="arm1">
    <visual>
      <geometry>
        <box size="0.1 0.1 1"/>
      </geometry>
      <material name="other"/>
    </visual>
    <collision>
      <geometry>
        <box size="0.1 0.1 1"/>
      </geometry>
    </collision>
    <inertial>
      <mass value="100"/>
      <origin rpy="0 0 0" xyz="0 0 0"/>
      <inertia ixx="0" ixy="0.0" ixz="0.0" iyy="0" iyz="0.0" izz="0"/>
    </inertial>
  </link>

  <joint name="axis1_arm1" type="fixed">
    <parent link="axis1"/>
    <child link="arm1"/>
    <origin rpy="0 0 0" xyz="0 0 .55"/>
  </joint>

  <link name="axis2">
    <visual>
      <geometry>
        <box size="0.1 0.1 0.1"/>
      </geometry>
      <material name="blue"/>
    </visual>
    <collision>
      <geometry>
        <box size="0.1 0.1 0.1"/>
      </geometry>
    </collision>
    <inertial>
      <mass value="100"/>
      <origin rpy="0 0 0" xyz="0 0 0"/>
      <inertia ixx="0" ixy="0.0" ixz="0.0" iyy="0" iyz="0.0" izz="0"/>
    </inertial>
  </link>

  <joint name="arm1_axis2" type="revolute"><!--Make revolute joint later-->
    <axis xyz="0 1 0"/>
    <parent link="arm1"/>
    <child link="axis2"/>
    <limit effort="0" lower="1" upper="0" velocity="205"/>
    <origin rpy="0 0 0" xyz="0 0 .65"/>
  </joint>

  <link name="arm2">
    <visual>
      <geometry>
        <box size="0.1 0.1 2"/>                                 <!--aparatus legnth increment-->
      </geometry>
      <material name="other"/>
    </visual>
    <collision>
      <geometry>
        <box size="0.1 0.1 2"/>                                 <!--aparatus legnth increment-->
      </geometry>
    </collision>
    <inertial>
      <mass value="100"/>
      <origin rpy="0 0 0" xyz="0 0 0"/>
      <inertia ixx="0" ixy="0.0" ixz="0.0" iyy="0" iyz="0.0" izz="0"/>
    </inertial>
  </link>

  <joint name="axis2_arm2" type="fixed">
    <parent link="axis2"/>
    <child link="arm2"/>
    <origin rpy="0 1.57075 0" xyz="1.05 0 0"/>    <!--ANGLE DISPLACEMENT!!!-->     <!--aparatus legnth increment-->
  </joint>

  <link name="axis3">
    <visual>
      <geometry>
        <box size="0.1 0.1 0.1"/>
      </geometry>
      <material name="blue"/>
    </visual>
    <collision>
      <geometry>
        <box size="0.1 0.1 0.1"/>
      </geometry>
    </collision>
    <inertial>
      <mass value="100"/>
      <origin rpy="0 0 0" xyz="0 0 0"/>
      <inertia ixx="0" ixy="0.0" ixz="0.0" iyy="0" iyz="0.0" izz="0"/>
    </inertial>
  </link>

  <joint name="arm2_axis3" type="revolute">    <!--Make revolute joint later-->
    <axis xyz="0 1 0"/>
    <parent link="arm2"/>
    <child link="axis3"/>
    <limit effort="0" lower="1" upper="0" velocity="205"/>
    <origin rpy="0 0 0" xyz="0 0 1.05"/>                      <!--aparatus legnth increment-->
  </joint>

  <link name="arm3">
    <visual>
      <geometry>
        <box size="0.1 0.1 1"/>
      </geometry>
      <material name="other"/>
    </visual>
    <collision>
      <geometry>
        <box size="0.1 0.1 1"/>
      </geometry>
    </collision>
    <inertial>
      <mass value="100"/>
      <origin rpy="0 0 0" xyz="0 0 0"/>
      <inertia ixx="0" ixy="0.0" ixz="0.0" iyy="0" iyz="0.0" izz="0"/>
    </inertial>
  </link>

  <joint name="axis3_arm3" type="fixed">    
    <parent link="axis3"/>
    <child link="arm3"/>
    <origin rpy="0 1.57075 0" xyz="0.65 0 0"/>    <!--ANGLE DISPLACEMENT!!!-->
  </joint>

  <link name="axis4">
    <visual>
      <geometry>
        <box size="0.1 0.1 0.1"/>
      </geometry>
      <material name="blue"/>
    </visual>
    <collision>
      <geometry>
        <box size="0.1 0.1 0.1"/>
      </geometry>
    </collision>
    <inertial>
      <mass value="100"/>
      <origin rpy="0 0 0" xyz="0 0 0"/>
      <inertia ixx="0" ixy="0.0" ixz="0.0" iyy="0" iyz="0.0" izz="0"/>
    </inertial>
  </link>

  <joint name="arm3_axis4" type="fixed">
    <!--DO NOT Make revolute joint later-->
    <!--axis xyz="0 1 0"/-->
    <parent link="arm3"/>
    <child link="axis4"/>
    <!--limit effort="0" lower="1" upper="0" velocity="205"/-->
    <origin rpy="0 0 0" xyz="0 0 .55"/>
  </joint>



  <link name="axis5">
    <visual>
      <geometry>
        <box size="0.1 0.1 0.1"/>
      </geometry>
      <material name="other"/>
    </visual>
    <collision>
      <geometry>
        <box size="0.1 0.1 0.1"/>
      </geometry>
    </collision>
    <inertial>
      <mass value="100"/>
      <origin rpy="0 0 0" xyz="0 0 0"/>
      <inertia ixx="0" ixy="0.0" ixz="0.0" iyy="0" iyz="0.0" izz="0"/>
    </inertial>
  </link>

  <joint name="axis4_axis5" type="revolute">
    <axis xyz="0 1 0"/>
    <parent link="axis4"/>
    <child link="axis5"/>
    <limit effort="0" lower="1" upper="0" velocity="205"/>
    <origin rpy="0 0 0" xyz="0 -.1 0"/>
  </joint>



  <!--cyclic body because of this joint!-->
  <!--Make revolute joint later:-->
  <!--joint name="axis4_base3" type="fixed">
    <parent link="axis4"/>
    <child link="base3"/>
    <origin rpy="0 0 0" xyz="-0.1 -.2 0.45"/>
  </joint-->

  <!--joint name="Base_axis1" type="fixed">
    <parent link="Base"/>
    <child link="axis1"/>
    <origin rpy="0 0 0" xyz=".1 .2 .45"/>
  </joint-->


</robot>  