<?xml version="1.0"?>
<robot name="myfirst">
  <material name="blue">
    <color rgba="0 0 0.8 1"/>
  </material>
  <material name="white">
    <color rgba="1 1 1 1"/>
  </material>
  <material name="other">
    <color rgba="1 0 0.8 1"/>
  </material>
  <velocity name="vel">
    <speed spd="50"/>
  </velocity>
    
  <!--Moving mechanism-->
  
  <link name="pulley1">
    <visual>
      <geometry>
        <cylinder length=".1" radius=".5"/>
      </geometry>
      <material name="blue"/>
    </visual>
    <collision>
      <geometry>
        <cylinder length=".1" radius=".5"/>
      </geometry>
    </collision>
    <inertial>
      <mass value="100"/>
      <inertia ixx="0" ixy="0.0" ixz="0.0" iyy="0" iyz="0.0" izz="0"/>
    </inertial>
  </link>

  <link name="tendon1_1">
    <visual>
      <geometry>
        <cylinder length=".1" radius=".05"/>
      </geometry>
      <material name="blue"/>
    </visual>
    <collision>
      <geometry>
        <cylinder length=".1" radius=".05"/>
      </geometry>
    </collision>
    <inertial>
      <mass value="10"/>
      <inertia ixx="0" ixy="0.0" ixz="0.0" iyy="0" iyz="0.0" izz="0"/>
    </inertial>
  </link>
  
  <joint name="pulley1_tendon1_1" type="revolute">
    <axis xyz="0 0 1"/>
    <parent link="pulley1"/>
    <child link="tendon1_1"/>
    <limit effort="0" lower="1" upper="0" velocity="50"/>
    <origin rpy="0 0 0" xyz="0 .55 0"/>
  </joint>

  <link name="tendon1_2">
    <visual>
      <geometry>
        <cylinder length=".1" radius=".05"/>
      </geometry>
      <material name="white"/>
    </visual>
    <collision>
      <geometry>
        <cylinder length=".1" radius=".05"/>
      </geometry>
    </collision>
    <inertial>
      <mass value="10"/>
      <inertia ixx="0" ixy="0.0" ixz="0.0" iyy="0" iyz="0.0" izz="0"/>
    </inertial>
  </link>
  <joint name="tendon1_1_tendon1_2" type="revolute">
    <axis xyz="0 0 1"/>
    <parent link="tendon1_1"/>
    <child link="tendon1_2"/>
    <limit effort="0" lower="1" upper="0" velocity="50"/>
    <origin rpy="0 0 0" xyz=".4 0 0"/>
  </joint>

  <link name="tendon1_3">
    <visual>
      <geometry>
        <cylinder length=".1" radius=".05"/>
      </geometry>
      <material name="white"/>
    </visual>
    <collision>
      <geometry>
        <cylinder length=".1" radius=".05"/>
      </geometry>
    </collision>
    <inertial>
      <mass value="10"/>
      <inertia ixx="0" ixy="0.0" ixz="0.0" iyy="0" iyz="0.0" izz="0"/>
    </inertial>
  </link>
  <joint name="tendon1_2_tendon1_3" type="revolute">
    <axis xyz="0 0 1"/>
    <parent link="tendon1_2"/>
    <child link="tendon1_3"/>
    <limit effort="0" lower="1" upper="0" velocity="50"/>
    <origin rpy="0 0 0" xyz=".4 0 0"/>
  </joint>

  <link name="tendon1_4">
    <visual>
      <geometry>
        <cylinder length=".1" radius=".05"/>
      </geometry>
      <material name="white"/>
    </visual>
    <collision>
      <geometry>
        <cylinder length=".1" radius=".05"/>
      </geometry>
    </collision>
    <inertial>
      <mass value="10"/>
      <inertia ixx="0" ixy="0.0" ixz="0.0" iyy="0" iyz="0.0" izz="0"/>
    </inertial>
  </link>
  <joint name="tendon1_3_tendon1_4" type="revolute">
    <axis xyz="0 0 1"/>
    <parent link="tendon1_3"/>
    <child link="tendon1_4"/>
    <limit effort="0" lower="1" upper="0" velocity="50"/>
    <origin rpy="0 0 0" xyz=".4 0 0"/>
  </joint>

  <link name="tendon1_5">
    <visual>
      <geometry>
        <cylinder length=".1" radius=".05"/>
      </geometry>
      <material name="white"/>
    </visual>
    <collision>
      <geometry>
        <cylinder length=".1" radius=".05"/>
      </geometry>
    </collision>
    <inertial>
      <mass value="10"/>
      <inertia ixx="0" ixy="0.0" ixz="0.0" iyy="0" iyz="0.0" izz="0"/>
    </inertial>
  </link>
  <joint name="tendon1_4_tendon1_5" type="revolute">
    <axis xyz="0 0 1"/>
    <parent link="tendon1_4"/>
    <child link="tendon1_5"/>
    <limit effort="0" lower="1" upper="0" velocity="50"/>
    <origin rpy="0 0 0" xyz=".4 0 0"/>
  </joint>


  <link name="cart">
    <visual>
      <geometry>
        <box size="0.3 0.6 .1"/>
        <!--Short base-->
      </geometry>
      <material name="blue"/>
    </visual>
    <collision>
      <geometry>
        <box size="0.1 0.6 .1"/>
        <!--short base-->
      </geometry>
    </collision>
    <inertial>
      <mass value="100"/>
      <origin rpy="0 0 0" xyz="0 0 0"/>
      <inertia ixx="0" ixy="0.0" ixz="0.0" iyy="0" iyz="0.0" izz="0"/>
    </inertial>
  </link>
  <joint name="tendon1_5_cart" type="fixed">
    <axis xyz="0 0 1"/>
    <parent link="tendon1_5"/>
    <child link="cart"/>
    <limit effort="0" lower="1" upper="0" velocity="50"/>
    <origin rpy="-1.57075 0 0" xyz=".45 0 0"/>
  </joint>

  <link name="tendon2_1">
    <visual>
      <geometry>
        <cylinder length=".1" radius=".05"/>
      </geometry>
      <material name="white"/>
    </visual>
    <collision>
      <geometry>
        <cylinder length=".1" radius=".05"/>
      </geometry>
    </collision>
    <inertial>
      <mass value="10"/>
      <inertia ixx="0" ixy="0.0" ixz="0.0" iyy="0" iyz="0.0" izz="0"/>
    </inertial>
  </link>
  <joint name="cart_tendon2_1" type="revolute">
    <axis xyz="0 0 1"/>
    <parent link="cart"/>
    <child link="tendon2_1"/>
    <limit effort="0" lower="1" upper="0" velocity="50"/>
    <origin rpy="1.57075 0 0" xyz=".45 0 0"/>
  </joint>

  <link name="tendon2_2">
    <visual>
      <geometry>
        <cylinder length=".1" radius=".05"/>
      </geometry>
      <material name="white"/>
    </visual>
    <collision>
      <geometry>
        <cylinder length=".1" radius=".05"/>
      </geometry>
    </collision>
    <inertial>
      <mass value="10"/>
      <inertia ixx="0" ixy="0.0" ixz="0.0" iyy="0" iyz="0.0" izz="0"/>
    </inertial>
  </link>
  <joint name="tendon2_1_tendon2_2" type="revolute">
    <axis xyz="0 0 1"/>
    <parent link="tendon2_1"/>
    <child link="tendon2_2"/>
    <limit effort="0" lower="1" upper="0" velocity="50"/>
    <origin rpy="0 0 0" xyz=".2 0 0"/>
  </joint>

  <link name="tendon2_3">
    <visual>
      <geometry>
        <cylinder length=".1" radius=".05"/>
      </geometry>
      <material name="white"/>
    </visual>
    <collision>
      <geometry>
        <cylinder length=".1" radius=".05"/>
      </geometry>
    </collision>
    <inertial>
      <mass value="10"/>
      <inertia ixx="0" ixy="0.0" ixz="0.0" iyy="0" iyz="0.0" izz="0"/>
    </inertial>
  </link>
  <joint name="tendon2_2_tendon2_3" type="revolute">
    <axis xyz="0 0 1"/>
    <parent link="tendon2_2"/>
    <child link="tendon2_3"/>
    <limit effort="0" lower="1" upper="0" velocity="50"/>
    <origin rpy="0 0 0" xyz=".2 0 0"/>
  </joint>

  <link name="tendon2_4">
    <visual>
      <geometry>
        <cylinder length=".1" radius=".05"/>
      </geometry>
      <material name="white"/>
    </visual>
    <collision>
      <geometry>
        <cylinder length=".1" radius=".05"/>
      </geometry>
    </collision>
    <inertial>
      <mass value="10"/>
      <inertia ixx="0" ixy="0.0" ixz="0.0" iyy="0" iyz="0.0" izz="0"/>
    </inertial>
  </link>
  <joint name="tendon2_3_tendon2_4" type="revolute">
    <axis xyz="0 0 1"/>
    <parent link="tendon2_3"/>
    <child link="tendon2_4"/>
    <limit effort="0" lower="1" upper="0" velocity="50"/>
    <origin rpy="0 0 0" xyz=".2 0 0"/>
  </joint>

  <link name="tendon2_5">
    <visual>
      <geometry>
        <cylinder length=".1" radius=".05"/>
      </geometry>
      <material name="white"/>
    </visual>
    <collision>
      <geometry>
        <cylinder length=".1" radius=".05"/>
      </geometry>
    </collision>
    <inertial>
      <mass value="10"/>
      <inertia ixx="0" ixy="0.0" ixz="0.0" iyy="0" iyz="0.0" izz="0"/>
    </inertial>
  </link>
  <joint name="tendon2_4_tendon2_5" type="revolute">
    <axis xyz="0 0 1"/>
    <parent link="tendon2_4"/>
    <child link="tendon2_5"/>
    <limit effort="0" lower="1" upper="0" velocity="50"/>
    <origin rpy="0 0 0" xyz=".2 0 0"/>
  </joint>

  <link name="tendon2_6">
    <visual>
      <geometry>
        <cylinder length=".1" radius=".05"/>
      </geometry>
      <material name="white"/>
    </visual>
    <collision>
      <geometry>
        <cylinder length=".1" radius=".05"/>
      </geometry>
    </collision>
    <inertial>
      <mass value="10"/>
      <inertia ixx="0" ixy="0.0" ixz="0.0" iyy="0" iyz="0.0" izz="0"/>
    </inertial>
  </link>
  <joint name="tendon2_5_tendon2_6" type="revolute">
    <axis xyz="0 0 1"/>
    <parent link="tendon2_5"/>
    <child link="tendon2_6"/>
    <limit effort="0" lower="1" upper="0" velocity="50"/>
    <origin rpy="0 0 0" xyz=".2 0 0"/>
  </joint>

  <link name="tendon2_7">
    <visual>
      <geometry>
        <cylinder length=".1" radius=".05"/>
      </geometry>
      <material name="white"/>
    </visual>
    <collision>
      <geometry>
        <cylinder length=".1" radius=".05"/>
      </geometry>
    </collision>
    <inertial>
      <mass value="10"/>
      <inertia ixx="0" ixy="0.0" ixz="0.0" iyy="0" iyz="0.0" izz="0"/>
    </inertial>
  </link>
  <joint name="tendon2_6_tendon2_7" type="revolute">
    <axis xyz="0 0 1"/>
    <parent link="tendon2_6"/>
    <child link="tendon2_7"/>
    <limit effort="0" lower="1" upper="0" velocity="50"/>
    <origin rpy="0 0 0" xyz=".2 0 0"/>
  </joint>

  <link name="tendon2_8">
    <visual>
      <geometry>
        <cylinder length=".1" radius=".05"/>
      </geometry>
      <material name="white"/>
    </visual>
    <collision>
      <geometry>
        <cylinder length=".1" radius=".05"/>
      </geometry>
    </collision>
    <inertial>
      <mass value="10"/>
      <inertia ixx="0" ixy="0.0" ixz="0.0" iyy="0" iyz="0.0" izz="0"/>
    </inertial>
  </link>
  <joint name="tendon2_7_tendon2_8" type="revolute">
    <axis xyz="0 0 1"/>
    <parent link="tendon2_7"/>
    <child link="tendon2_8"/>
    <limit effort="0" lower="1" upper="0" velocity="50"/>
    <origin rpy="0 0 0" xyz=".2 0 0"/>
  </joint>

  <link name="tendon2_9">
    <visual>
      <geometry>
        <cylinder length=".1" radius=".05"/>
      </geometry>
      <material name="blue"/>
    </visual>
    <collision>
      <geometry>
        <cylinder length=".1" radius=".05"/>
      </geometry>
    </collision>
    <inertial>
      <mass value="10"/>
      <inertia ixx="0" ixy="0.0" ixz="0.0" iyy="0" iyz="0.0" izz="0"/>
    </inertial>
  </link>
  <joint name="tendon2_8_tendon2_9" type="revolute">
    <axis xyz="0 0 1"/>
    <parent link="tendon2_8"/>
    <child link="tendon2_9"/>
    <limit effort="0" lower="1" upper="0" velocity="50"/>
    <origin rpy="0 0 -.364" xyz=".2 0 0"/>
  </joint>

  <link name="tendon2_10">
    <visual>
      <geometry>
        <cylinder length=".1" radius=".05"/>
      </geometry>
      <material name="white"/>
    </visual>
    <collision>
      <geometry>
        <cylinder length=".1" radius=".05"/>
      </geometry>
    </collision>
    <inertial>
      <mass value="10"/>
      <inertia ixx="0" ixy="0.0" ixz="0.0" iyy="0" iyz="0.0" izz="0"/>
    </inertial>
  </link>
  <joint name="tendon2_9_tendon2_10" type="revolute">
    <axis xyz="0 0 1"/>
    <parent link="tendon2_9"/>
    <child link="tendon2_10"/>
    <limit effort="0" lower="1" upper="0" velocity="50"/>
    <origin rpy="0 0 -.364" xyz=".2 0 0"/>
  </joint>

  <link name="tendon2_11">
    <visual>
      <geometry>
        <cylinder length=".1" radius=".05"/>
      </geometry>
      <material name="white"/>
    </visual>
    <collision>
      <geometry>
        <cylinder length=".1" radius=".05"/>
      </geometry>
    </collision>
    <inertial>
      <mass value="10"/>
      <inertia ixx="0" ixy="0.0" ixz="0.0" iyy="0" iyz="0.0" izz="0"/>
    </inertial>
  </link>
  <joint name="tendon2_10_tendon2_11" type="revolute">
    <axis xyz="0 0 1"/>
    <parent link="tendon2_10"/>
    <child link="tendon2_11"/>
    <limit effort="0" lower="1" upper="0" velocity="50"/>
    <origin rpy="0 0 -.364" xyz=".2 0 0"/>
  </joint>

  <link name="tendon2_12">
    <visual>
      <geometry>
        <cylinder length=".1" radius=".05"/>
      </geometry>
      <material name="white"/>
    </visual>
    <collision>
      <geometry>
        <cylinder length=".1" radius=".05"/>
      </geometry>
    </collision>
    <inertial>
      <mass value="10"/>
      <inertia ixx="0" ixy="0.0" ixz="0.0" iyy="0" iyz="0.0" izz="0"/>
    </inertial>
  </link>
  <joint name="tendon2_11_tendon2_12" type="revolute">
    <axis xyz="0 0 1"/>
    <parent link="tendon2_11"/>
    <child link="tendon2_12"/>
    <limit effort="0" lower="1" upper="0" velocity="50"/>
    <origin rpy="0 0 -.364" xyz=".2 0 0"/>
  </joint>

  <link name="tendon2_13">
    <visual>
      <geometry>
        <cylinder length=".1" radius=".05"/>
      </geometry>
      <material name="white"/>
    </visual>
    <collision>
      <geometry>
        <cylinder length=".1" radius=".05"/>
      </geometry>
    </collision>
    <inertial>
      <mass value="10"/>
      <inertia ixx="0" ixy="0.0" ixz="0.0" iyy="0" iyz="0.0" izz="0"/>
    </inertial>
  </link>
  <joint name="tendon2_12_tendon2_13" type="revolute">
    <axis xyz="0 0 1"/>
    <parent link="tendon2_12"/>
    <child link="tendon2_13"/>
    <limit effort="0" lower="1" upper="0" velocity="50"/>
    <origin rpy="0 0 -.364" xyz=".2 0 0"/>
  </joint>

  <link name="tendon2_14">
    <visual>
      <geometry>
        <cylinder length=".1" radius=".05"/>
      </geometry>
      <material name="white"/>
    </visual>
    <collision>
      <geometry>
        <cylinder length=".1" radius=".05"/>
      </geometry>
    </collision>
    <inertial>
      <mass value="10"/>
      <inertia ixx="0" ixy="0.0" ixz="0.0" iyy="0" iyz="0.0" izz="0"/>
    </inertial>
  </link>
  <joint name="tendon2_13_tendon2_14" type="revolute">
    <axis xyz="0 0 1"/>
    <parent link="tendon2_13"/>
    <child link="tendon2_14"/>
    <limit effort="0" lower="1" upper="0" velocity="50"/>
    <origin rpy="0 0 -.364" xyz=".2 0 0"/>
  </joint>

  <link name="tendon2_15">
    <visual>
      <geometry>
        <cylinder length=".1" radius=".05"/>
      </geometry>
      <material name="white"/>
    </visual>
    <collision>
      <geometry>
        <cylinder length=".1" radius=".05"/>
      </geometry>
    </collision>
    <inertial>
      <mass value="10"/>
      <inertia ixx="0" ixy="0.0" ixz="0.0" iyy="0" iyz="0.0" izz="0"/>
    </inertial>
  </link>
  <joint name="tendon2_14_tendon2_15" type="revolute">
    <axis xyz="0 0 1"/>
    <parent link="tendon2_14"/>
    <child link="tendon2_15"/>
    <limit effort="0" lower="1" upper="0" velocity="50"/>
    <origin rpy="0 0 -.364" xyz=".2 0 0"/>
  </joint>

  <link name="tendon2_16">
    <visual>
      <geometry>
        <cylinder length=".1" radius=".05"/>
      </geometry>
      <material name="white"/>
    </visual>
    <collision>
      <geometry>
        <cylinder length=".1" radius=".05"/>
      </geometry>
    </collision>
    <inertial>
      <mass value="10"/>
      <inertia ixx="0" ixy="0.0" ixz="0.0" iyy="0" iyz="0.0" izz="0"/>
    </inertial>
  </link>
  <joint name="tendon2_15_tendon2_16" type="revolute">
    <axis xyz="0 0 1"/>
    <parent link="tendon2_15"/>
    <child link="tendon2_16"/>
    <limit effort="0" lower="1" upper="0" velocity="50"/>
    <origin rpy="0 0 -.364" xyz=".2 0 0"/>
  </joint>

  <link name="pulley2">
    <visual>
      <geometry>
        <cylinder length=".1" radius=".5"/>
      </geometry>
      <material name="blue"/>
    </visual>
    <collision>
      <geometry>
        <cylinder length=".1" radius=".5"/>
      </geometry>
    </collision>
    <inertial>
      <mass value="10"/>
      <inertia ixx="0" ixy="0.0" ixz="0.0" iyy="0" iyz="0.0" izz="0"/>
    </inertial>
  </link>
  <joint name="tendon2_16_pulley2" type="fixed">
    <parent link="tendon2_16"/>
    <child link="pulley2"/>
    <origin rpy="0 0 0" xyz="0 -.55 0"/>
  </joint>
<!--
  <link name="axis2">
    <visual>
      <geometry>
        <cylinder length=".1" radius=".047"/>
      </geometry>
      <material name="white"/>
    </visual>
    <collision>
      <geometry>
        <cylinder length=".1" radius=".047"/>
      </geometry>
    </collision>
    <inertial>
      <mass value="10"/>
      <inertia ixx="0" ixy="0.0" ixz="0.0" iyy="0" iyz="0.0" izz="0"/>
    </inertial>
  </link>
  <joint name="pulley2_axis2" type="fixed">
    <parent link="pulley2"/>
    <child link="axis2"/>
    <origin rpy="0 0 0" xyz="0 0 .05"/>
  </joint>

  <link name="cube">
    <visual>
      <geometry>
        <box size="0.1 0.1 0.1"/>
      </geometry>
      <material name="other"/>
    </visual>
    <collision>
      <geometry>
        <box size="0.1 0.1 0.1"/>
      </geometry>
    </collision>
    <inertial>
      <mass value="100"/>
      <origin rpy="0 0 0" xyz="0 0 0"/>
      <inertia ixx="0" ixy="0.0" ixz="0.0" iyy="0" iyz="0.0" izz="0"/>
    </inertial>
  </link>
  <joint name="axis2_cube" type="revolute">
    <axis xyz="0 0 1"/>
    <parent link="axis2"/>
    <child link="cube"/>
    <limit effort="0" lower="1" upper="0" velocity="vel"/>
    <origin rpy="0 0 0" xyz="0 0 .1"/>
  </joint>
-->
</robot>  